Workbook

Sheet Cover
B2: MERIDIAN RISK TECHNOLOGIES
B3: FY26 Sales Commission & FP&A Model
B4: Financial Planning & Analysis — Sales Compensation
B6: Prepared by: | C6: FP&A — Sales Compensation Analyst
B7: Period covered: | C7: Q1–Q2 FY26 (Jan–Jun 2026), with Q3 FY26 forecast
B8: Last updated: | C8: =TODAY() -> 46294
B9: Status: | C9: Final — recalculated and tie-out complete
B11: Purpose
B12: This workbook is the source of truth for FY26 sales commission calculations, attainment reporting, and accrual/forecast support. It replaces the prior manual spreadsheet process, which required three days of rep-by-rep reconciliation each month-end and produced inconsistent results across segments due to hand-entered tier lookups.
B17: How this workbook is organized
B18: Commission Plan Rules | C18: Tiered accelerator structure and rates. Change rates here — every downstream tab recalculates.
B19: Sales Roster & Quotas | C19: Rep roster, segment, quota, and existing book of business (renewal base).
B20: Bookings Detail | C20: Deal-level bookings (270 closed-won deals) with commission calculated line by line.
B21: Rep-Quarter Summary | C21: Attainment and commission rolled up by rep and quarter — the management review view.
B22: Monthly Accrual & Forecast | C22: Monthly commission accrual for the books and a Q3 forecast for budgeting.
B23: Executive Dashboard | C23: KPIs and trend charts for leadership reporting.
B26: Methodology & data notes
B27: • | C27: Commission is calculated at the deal level so any single booking can be audited back to its rate and tier.
B28: • | C28: New Business uses a marginal tiered accelerator (see Commission Plan Rules); Upsell and Renewal use flat rates.
B29: • | C29: Net Revenue Retention (NRR) is approximated as renewed ARR divided by the book of business eligible to renew in the period.
B30: • | C30: Source data was exported from the CRM and passed through a data-cleansing step (sign corrections, deduplication, and null handling) before loading — see the accompanying data-prep pipeline documentation.
B31: • | C31: Color key: blue text = input/assumption, black = calculated formula, green = link from another tab.

Sheet Commission Plan Rules
B2: FY26 Commission Plan — Rate Card
B3: Effective January 1, 2026. Rate changes require VP Sales + FP&A sign-off.
B5: Applies To | C5: Tier | D5: Attainment Floor | E5: Attainment Ceiling | F5: Rate | G5: Plan Logic
B6: New Business | C6: 1 | D6: 0 | E6: 1 | F6: 0.08 | G6: Base rate up to 100% of quarterly quota
B7: New Business | C7: 2 | D7: 1 | E7: 1.25 | F7: 0.1 | G7: Accelerator: 100%-125% of quota
B8: New Business | C8: 3 | D8: 1.25 | E8: Uncapped | F8: 0.12 | G8: Accelerator: above 125% of quota
B9: Upsell | C9: — | D9: 0 | E9: Uncapped | F9: 0.06 | G9: Flat rate on expansion ARR
B10: Renewal | C10: — | D10: 0 | E10: Uncapped | F10: 0.03 | G10: Retention SPIF on renewed ARR
B14: Named rate references (used by formulas on Bookings Detail):
B15: New Biz Tier 1 (0–100%) | C15: ='Commission Plan Rules'!$F$6 -> 0.08
B16: New Biz Tier 2 (100–125%) | C16: ='Commission Plan Rules'!$F$7 -> 0.1
B17: New Biz Tier 3 (125%+) | C17: ='Commission Plan Rules'!$F$8 -> 0.12
B18: Upsell flat rate | C18: ='Commission Plan Rules'!$F$9 -> 0.06
B19: Renewal flat rate | C19: ='Commission Plan Rules'!$F$10 -> 0.03
B22: Legend
B23: Yellow fill = key assumption (editable — plan changes flow through the whole model)

Sheet Sales Roster & Quotas
B2: FY26 Sales Roster & Quarterly Quotas
B3: Quota = new business ARR target per quarter. Book of business = ARR under management as of 1/1/2026 (renewal base).
B5: Rep ID | C5: Rep Name | D5: Segment | E5: Region | F5: Hire Date | G5: Quarterly Quota (New ARR) | H5: Starting Book of Business (ARR)
B6: R001 | C6: Maria Chen | D6: SMB | E6: West | F6: 2023-06-01 | G6: 160000 | H6: 302000
B7: R002 | C7: James Okafor | D7: SMB | E7: West | F7: 2025-09-01 | G7: 135000 | H7: 40000
B8: R003 | C8: Priya Patel | D8: SMB | E8: East | F8: 2023-07-01 | G8: 137000 | H8: 311000
B9: R004 | C9: David Nguyen | D9: SMB | E9: East | F9: 2024-07-01 | G9: 155000 | H9: 152000
B10: R005 | C10: Sofia Rossi | D10: SMB | E10: West | F10: 2022-11-01 | G10: 152000 | H10: 320000
B11: R006 | C11: Marcus Bennett | D11: SMB | E11: West | F11: 2023-01-01 | G11: 159000 | H11: 344000
B12: R007 | C12: Elena Kowalski | D12: Mid-Market | E12: East | F12: 2022-05-01 | G12: 320000 | H12: 580000
B13: R008 | C13: Tyler Alvarez | D13: Mid-Market | E13: West | F13: 2024-12-01 | G13: 275000 | H13: 297000
B14: R009 | C14: Aisha Kim | D14: Mid-Market | E14: East | F14: 2023-01-01 | G14: 287000 | H14: 609000
B15: R010 | C15: Ryan Sullivan | D15: Mid-Market | E15: Central | F15: 2023-04-01 | G15: 273000 | H15: 695000
B16: R011 | C16: Natalie Reyes | D16: Mid-Market | E16: West | F16: 2024-08-01 | G16: 295000 | H16: 321000
B17: R012 | C17: Omar Fischer | D17: Mid-Market | E17: East | F17: 2024-11-01 | G17: 324000 | H17: 262000
... B20: R015 | C20: Lucia Larsen | D20: Enterprise | E20: Central | F20: 2023-01-01 | G20: 594000 | H20: 1176000
C21: Total / Company | G21: =SUM(G6:G20) -> 4533000 | H21: =SUM(H6:H20) -> 7359000

Sheet Bookings Detail
A1: FY26 Bookings Detail — Deal-Level Commission Calculation
A2: Every closed-won deal, Jan–Jun 2026. Commission is computed per row so any figure can be traced back to its inputs. New Business commission uses the marginal tiered rate from Commission Plan Rules; Upsell and Renewal use flat rates.
A4: Deal ID | B4: Rep ID | C4: Rep Name | D4: Segment | E4: Close Date | F4: Month | G4: Quarter | H4: Deal Type | I4: Customer | J4: Product Line | K4: ARR Amount | L4: Quota (Qtr) | M4: New Biz ARR (Qtr, this rep) | N4: Attainment % | O4: Tier 1 Amt | P4: Tier 2 Amt | Q4: Tier 3 Amt | R4: New Biz Commission (Qtr) | S4: Commission Amount
A5: D00033 | B5: R002 | C5: =IFERROR(INDEX('Sales Roster & Quotas'!$C$6:$C$20,MATCH($B5,'Sales Roster & Quotas'!$B$6:$B$20,0)),"") -> James Okafor | D5: =IFERROR(INDEX('Sales Roster & Quotas'!$D$6:$D$20,MATCH($B5,'Sales Roster & Quotas'!$B$6:$B$20,0)),"") -> SMB | E5: 46024 | F5: =TEXT(E5,"yyyy-mm") -> 2026-01 | G5: =IF(MONTH(E5)<=3,"Q1","Q2") -> Q1 | H5: Renewal | I5: Millbrook Coverage Partners | J5: Policy Admin Core | K5: 8500 | L5: =IFERROR(INDEX('Sales Roster & Quotas'!$G$6:$G$20,MATCH($B5,'Sales Roster & Quotas'!$B$6:$B$20,0)),0) -> 135000 | M5: =SUMIFS($K$5:$K$274,$B$5:$B$274,$B5,$G$5:$G$274,$G5,$H$5:$H$274,"New Business") -> 170500 | N5: =IFERROR(M5/L5,0) -> 1.262963 | O5: =MIN(M5,L5) -> 135000 | P5: =MAX(MIN(M5,L5*1.25)-L5,0) -> 33750 | Q5: =MAX(M5-L5*1.25,0) -> 1750 | R5: =O5*'Commission Plan Rules'!$F$6+P5*'Commission Plan Rules'!$F$7+Q5*'Commission Plan Rules'!$F$8 -> 14385 | S5: =IF(H5="New Business",IFERROR((K5/M5)*R5,0),IF(H5="Upsell",K5*'Commission Plan Rules'!$F$9,IF(H5="Renewal",K5*'Commission Plan Rules'!$F$10,0))) -> 255
A6: D00133 | B6: R007 | C6: =IFERROR(INDEX('Sales Roster & Quotas'!$C$6:$C$20,MATCH($B6,'Sales Roster & Quotas'!$B$6:$B$20,0)),"") -> Elena Kowalski | D6: =IFERROR(INDEX('Sales Roster & Quotas'!$D$6:$D$20,MATCH($B6,'Sales Roster & Quotas'!$B$6:$B$20,0)),"") -> Mid-Market | E6: 46025 | F6: =TEXT(E6,"yyyy-mm") -> 2026-01 | G6: =IF(MONTH(E6)<=3,"Q1","Q2") -> Q1 | H6: Renewal | I6: Windham Insurance Brokers | J6: Policy Admin Core | K6: 140000 | L6: =IFERROR(INDEX('Sales Roster & Quotas'!$G$6:$G$20,MATCH($B6,'Sales Roster & Quotas'!$B$6:$B$20,0)),0) -> 320000 | M6: =SUMIFS($K$5:$K$274,$B$5:$B$274,$B6,$G$5:$G$274,$G6,$H$5:$H$274,"New Business") -> 259000 | N6: =IFERROR(M6/L6,0) -> 0.809375 | O6: =MIN(M6,L6) -> 259000 | P6: =MAX(MIN(M6,L6*1.25)-L6,0) -> 0 | Q6: =MAX(M6-L6*1.25,0) -> 0 | R6: =O6*'Commission Plan Rules'!$F$6+P6*'Commission Plan Rules'!$F$7+Q6*'Commission Plan Rules'!$F$8 -> 20720 | S6: =IF(H6="New Business",IFERROR((K6/M6)*R6,0),IF(H6="Upsell",K6*'Commission Plan Rules'!$F$9,IF(H6="Renewal",K6*'Commission Plan Rules'!$F$10,0))) -> 4200
A7: D00219 | B7: R012 | C7: =IFERROR(INDEX('Sales Roster & Quotas'!$C$6:$C$20,MATCH($B7,'Sales Roster & Quotas'!$B$6:$B$20,0)),"") -> Omar Fischer | D7: =IFERROR(INDEX('Sales Roster & Quotas'!$D$6:$D$20,MATCH($B7,'Sales Roster & Quotas'!$B$6:$B$20,0)),"") -> Mid-Market | E7: 46026 | F7: =TEXT(E7,"yyyy-mm") -> 2026-01 | G7: =IF(MONTH(E7)<=3,"Q1","Q2") -> Q1 | H7: Upsell | I7: Redwood Insurance Solutions | J7: Claims Module | K7: 25000 | L7: =IFERROR(INDEX('Sales Roster & Quotas'!$G$6:$G$20,MATCH($B7,'Sales Roster & Quotas'!$B$6:$B$20,0)),0) -> 324000 | M7: =SUMIFS($K$5:$K$274,$B$5:$B$274,$B7,$G$5:$G$274,$G7,$H$5:$H$274,"New Business") -> 457000 | N7: =IFERROR(M7/L7,0) -> 1.4104938 | O7: =MIN(M7,L7) -> 324000 | P7: =MAX(MIN(M7,L7*1.25)-L7,0) -> 81000 | Q7: =MAX(M7-L7*1.25,0) -> 52000 | R7: =O7*'Commission Plan Rules'!$F$6+P7*'Commission Plan Rules'!$F$7+Q7*'Commission Plan Rules'!$F$8 -> 40260 | S7: =IF(H7="New Business",IFERROR((K7/M7)*R7,0),IF(H7="Upsell",K7*'Commission Plan Rules'!$F$9,IF(H7="Renewal",K7*'Commission Plan Rules'!$F$10,0))) -> 1500
A8: D00069 | B8: R004 | C8: =IFERROR(INDEX('Sales Roster & Quotas'!$C$6:$C$20,MATCH($B8,'Sales Roster & Quotas'!$B$6:$B$20,0)),"") -> David Nguyen | D8: =IFERROR(INDEX('Sales Roster & Quotas'!$D$6:$D$20,MATCH($B8,'Sales Roster & Quotas'!$B$6:$B$20,0)),"") -> SMB | E8: 46027 | F8: =TEXT(E8,"yyyy-mm") -> 2026-01 | G8: =IF(MONTH(E8)<=3,"Q1","Q2") -> Q1 | H8: Upsell | I8: Harborview Mutual Agency | J8: Policy Admin Core | K8: 12500 | L8: =IFERROR(INDEX('Sales Roster & Quotas'!$G$6:$G$20,MATCH($B8,'Sales Roster & Quotas'!$B$6:$B$20,0)),0) -> 155000 | M8: =SUMIFS($K$5:$K$274,$B$5:$B$274,$B8,$G$5:$G$274,$G8,$H$5:$H$274,"New Business") -> 196500 | N8: =IFERROR(M8/L8,0) -> 1.2677419 | O8: =MIN(M8,L8) -> 155000 | P8: =MAX(MIN(M8,L8*1.25)-L8,0) -> 38750 | Q8: =MAX(M8-L8*1.25,0) -> 2750 | R8: =O8*'Commission Plan Rules'!$F$6+P8*'Commission Plan Rules'!$F$7+Q8*'Commission Plan Rules'!$F$8 -> 16605 | S8: =IF(H8="New Business",IFERROR((K8/M8)*R8,0),IF(H8="Upsell",K8*'Commission Plan Rules'!$F$9,IF(H8="Renewal",K8*'Commission Plan Rules'!$F$10,0))) -> 750
A9: D00188 | B9: R010 | C9: =IFERROR(INDEX('Sales Roster & Quotas'!$C$6:$C$20,MATCH($B9,'Sales Roster & Quotas'!$B$6:$B$20,0)),"") -> Ryan Sullivan | D9: =IFERROR(INDEX('Sales Roster & Quotas'!$D$6:$D$20,MATCH($B9,'Sales Roster & Quotas'!$B$6:$B$20,0)),"") -> Mid-Market | E9: 46027 | F9: =TEXT(E9,"yyyy-mm") -> 2026-01 | G9: =IF(MONTH(E9)<=3,"Q1","Q2") -> Q1 | H9: Renewal | I9: Clearwater Underwriters | J9: Policy Admin Core | K9: 9500 | L9: =IFERROR(INDEX('Sales Roster & Quotas'!$G$6:$G$20,MATCH($B9,'Sales Roster & Quotas'!$B$6:$B$20,0)),0) -> 273000 | M9: =SUMIFS($K$5:$K$274,$B$5:$B$274,$B9,$G$5:$G$274,$G9,$H$5:$H$274,"New Business") -> 271000 | N9: =IFERROR(M9/L9,0) -> 0.99267399 | O9: =MIN(M9,L9) -> 271000 | P9: =MAX(MIN(M9,L9*1.25)-L9,0) -> 0 | Q9: =MAX(M9-L9*1.25,0) -> 0 | R9: =O9*'Commission Plan Rules'!$F$6+P9*'Commission Plan Rules'!$F$7+Q9*'Commission Plan Rules'!$F$8 -> 21680 | S9: =IF(H9="New Business",IFERROR((K9/M9)*R9,0),IF(H9="Upsell",K9*'Commission Plan Rules'!$F$9,IF(H9="Renewal",K9*'Commission Plan Rules'!$F$10,0))) -> 285
A10: D00004 | B10: R001 | C10: =IFERROR(INDEX('Sales Roster & Quotas'!$C$6:$C$20,MATCH($B10,'Sales Roster & Quotas'!$B$6:$B$20,0)),"") -> Maria Chen | D10: =IFERROR(INDEX('Sales Roster & Quotas'!$D$6:$D$20,MATCH($B10,'Sales Roster & Quotas'!$B$6:$B$20,0)),"") -> SMB | E10: 46027 | F10: =TEXT(E10,"yyyy-mm") -> 2026-01 | G10: =IF(MONTH(E10)<=3,"Q1","Q2") -> Q1 | H10: New Business | I10: Windham Insurance Brokers | J10: Claims Module | K10: 15500 | L10: =IFERROR(INDEX('Sales Roster & Quotas'!$G$6:$G$20,MATCH($B10,'Sales Roster & Quotas'!$B$6:$B$20,0)),0) -> 160000 | M10: =SUMIFS($K$5:$K$274,$B$5:$B$274,$B10,$G$5:$G$274,$G10,$H$5:$H$274,"New Business") -> 142000 | N10: =IFERROR(M10/L10,0) -> 0.8875 | O10: =MIN(M10,L10) -> 142000 | P10: =MAX(MIN(M10,L10*1.25)-L10,0) -> 0 | Q10: =MAX(M10-L10*1.25,0) -> 0 | R10: =O10*'Commission Plan Rules'!$F$6+P10*'Commission Plan Rules'!$F$7+Q10*'Commission Plan Rules'!$F$8 -> 11360 | S10: =IF(H10="New Business",IFERROR((K10/M10)*R10,0),IF(H10="Upsell",K10*'Commission Plan Rules'!$F$9,IF(H10="Renewal",K10*'Commission Plan Rules'!$F$10,0))) -> 1240
A11: D00145 | B11: R008 | C11: =IFERROR(INDEX('Sales Roster & Quotas'!$C$6:$C$20,MATCH($B11,'Sales Roster & Quotas'!$B$6:$B$20,0)),"") -> Tyler Alvarez | D11: =IFERROR(INDEX('Sales Roster & Quotas'!$D$6:$D$20,MATCH($B11,'Sales Roster & Quotas'!$B$6:$B$20,0)),"") -> Mid-Market | E11: 46027 | F11: =TEXT(E11,"yyyy-mm") -> 2026-01 | G11: =IF(MONTH(E11)<=3,"Q1","Q2") -> Q1 | H11: Upsell | I11: Coastal Insurance Group | J11: Policy Admin Core | K11: 33500 | L11: =IFERROR(INDEX('Sales Roster & Quotas'!$G$6:$G$20,MATCH($B11,'Sales Roster & Quotas'!$B$6:$B$20,0)),0) -> 275000 | M11: =SUMIFS($K$5:$K$274,$B$5:$B$274,$B11,$G$5:$G$274,$G11,$H$5:$H$274,"New Business") -> 260500 | N11: =IFERROR(M11/L11,0) -> 0.94727273 | O11: =MIN(M11,L11) -> 260500 | P11: =MAX(MIN(M11,L11*1.25)-L11,0) -> 0 | Q11: =MAX(M11-L11*1.25,0) -> 0 | R11: =O11*'Commission Plan Rules'!$F$6+P11*'Commission Plan Rules'!$F$7+Q11*'Commission Plan Rules'!$F$8 -> 20840 | S11: =IF(H11="New Business",IFERROR((K11/M11)*R11,0),IF(H11="Upsell",K11*'Commission Plan Rules'!$F$9,IF(H11="Renewal",K11*'Commission Plan Rules'!$F$10,0))) -> 2010
A12: D00200 | B12: R011 | C12: =IFERROR(INDEX('Sales Roster & Quotas'!$C$6:$C$20,MATCH($B12,'Sales Roster & Quotas'!$B$6:$B$20,0)),"") -> Natalie Reyes | D12: =IFERROR(INDEX('Sales Roster & Quotas'!$D$6:$D$20,MATCH($B12,'Sales Roster & Quotas'!$B$6:$B$20,0)),"") -> Mid-Market | E12: 46027 | F12: =TEXT(E12,"yyyy-mm") -> 2026-01 | G12: =IF(MONTH(E12)<=3,"Q1","Q2") -> Q1 | H12: Upsell | I12: Sterling Mutual Agency | J12: Analytics Add-On | K12: 12500 | L12: =IFERROR(INDEX('Sales Roster & Quotas'!$G$6:$G$20,MATCH($B12,'Sales Roster & Quotas'!$B$6:$B$20,0)),0) -> 295000 | M12: =SUMIFS($K$5:$K$274,$B$5:$B$274,$B12,$G$5:$G$274,$G12,$H$5:$H$274,"New Business") -> 267000 | N12: =IFERROR(M12/L12,0) -> 0.90508475 | O12: =MIN(M12,L12) -> 267000 | P12: =MAX(MIN(M12,L12*1.25)-L12,0) -> 0 | Q12: =MAX(M12-L12*1.25,0) -> 0 | R12: =O12*'Commission Plan Rules'!$F$6+P12*'Commission Plan Rules'!$F$7+Q12*'Commission Plan Rules'!$F$8 -> 21360 | S12: =IF(H12="New Business",IFERROR((K12/M12)*R12,0),IF(H12="Upsell",K12*'Commission Plan Rules'!$F$9,IF(H12="Renewal",K12*'Commission Plan Rules'!$F$10,0))) -> 750
A13: D00186 | B13: R010 | C13: =IFERROR(INDEX('Sales Roster & Quotas'!$C$6:$C$20,MATCH($B13,'Sales Roster & Quotas'!$B$6:$B$20,0)),"") -> Ryan Sullivan | D13: =IFERROR(INDEX('Sales Roster & Quotas'!$D$6:$D$20,MATCH($B13,'Sales Roster & Quotas'!$B$6:$B$20,0)),"") -> Mid-Market | E13: 46028 | F13: =TEXT(E13,"yyyy-mm") -> 2026-01 | G13: =IF(MONTH(E13)<=3,"Q1","Q2") -> Q1 | H13: Renewal | I13: Hillcrest Insurance Solutions | J13: Policy Admin Core | K13: 2000 | L13: =IFERROR(INDEX('Sales Roster & Quotas'!$G$6:$G$20,MATCH($B13,'Sales Roster & Quotas'!$B$6:$B$20,0)),0) -> 273000 | M13: =SUMIFS($K$5:$K$274,$B$5:$B$274,$B13,$G$5:$G$274,$G13,$H$5:$H$274,"New Business") -> 271000 | N13: =IFERROR(M13/L13,0) -> 0.99267399 | O13: =MIN(M13,L13) -> 271000 | P13: =MAX(MIN(M13,L13*1.25)-L13,0) -> 0 | Q13: =MAX(M13-L13*1.25,0) -> 0 | R13: =O13*'Commission Plan Rules'!$F$6+P13*'Commission Plan Rules'!$F$7+Q13*'Commission Plan Rules'!$F$8 -> 21680 | S13: =IF(H13="New Business",IFERROR((K13/M13)*R13,0),IF(H13="Upsell",K13*'Commission Plan Rules'!$F$9,IF(H13="Renewal",K13*'Commission Plan Rules'!$F$10,0))) -> 60
A14: D00030 | B14: R002 | C14: =IFERROR(INDEX('Sales Roster & Quotas'!$C$6:$C$20,MATCH($B14,'Sales Roster & Quotas'!$B$6:$B$20,0)),"") -> James Okafor | D14: =IFERROR(INDEX('Sales Roster & Quotas'!$D$6:$D$20,MATCH($B14,'Sales Roster & Quotas'!$B$6:$B$20,0)),"") -> SMB | E14: 46029 | F14: =TEXT(E14,"yyyy-mm") -> 2026-01 | G14: =IF(MONTH(E14)<=3,"Q1","Q2") -> Q1 | H14: Upsell | I14: Riverbend Coverage Partners | J14: Client Portal | K14: 2500 | L14: =IFERROR(INDEX('Sales Roster & Quotas'!$G$6:$G$20,MATCH($B14,'Sales Roster & Quotas'!$B$6:$B$20,0)),0) -> 135000 | M14: =SUMIFS($K$5:$K$274,$B$5:$B$274,$B14,$G$5:$G$274,$G14,$H$5:$H$274,"New Business") -> 170500 | N14: =IFERROR(M14/L14,0) -> 1.262963 | O14: =MIN(M14,L14) -> 135000 | P14: =MAX(MIN(M14,L14*1.25)-L14,0) -> 33750 | Q14: =MAX(M14-L14*1.25,0) -> 1750 | R14: =O14*'Commission Plan Rules'!$F$6+P14*'Commission Plan Rules'!$F$7+Q14*'Commission Plan Rules'!$F$8 -> 14385 | S14: =IF(H14="New Business",IFERROR((K14/M14)*R14,0),IF(H14="Upsell",K14*'Commission Plan Rules'!$F$9,IF(H14="Renewal",K14*'Commission Plan Rules'!$F$10,0))) -> 150
A15: D00265 | B15: R015 | C15: =IFERROR(INDEX('Sales Roster & Quotas'!$C$6:$C$20,MATCH($B15,'Sales Roster & Quotas'!$B$6:$B$20,0)),"") -> Lucia Larsen | D15: =IFERROR(INDEX('Sales Roster & Quotas'!$D$6:$D$20,MATCH($B15,'Sales Roster & Quotas'!$B$6:$B$20,0)),"") -> Enterprise | E15: 46029 | F15: =TEXT(E15,"yyyy-mm") -> 2026-01 | G15: =IF(MONTH(E15)<=3,"Q1","Q2") -> Q1 | H15: Renewal | I15: Ironwood Risk Advisors | J15: Policy Admin Core | K15: 3000 | L15: =IFERROR(INDEX('Sales Roster & Quotas'!$G$6:$G$20,MATCH($B15,'Sales Roster & Quotas'!$B$6:$B$20,0)),0) -> 594000 | M15: =SUMIFS($K$5:$K$274,$B$5:$B$274,$B15,$G$5:$G$274,$G15,$H$5:$H$274,"New Business") -> 542500 | N15: =IFERROR(M15/L15,0) -> 0.91329966 | O15: =MIN(M15,L15) -> 542500 | P15: =MAX(MIN(M15,L15*1.25)-L15,0) -> 0 | Q15: =MAX(M15-L15*1.25,0) -> 0 | R15: =O15*'Commission Plan Rules'!$F$6+P15*'Commission Plan Rules'!$F$7+Q15*'Commission Plan Rules'!$F$8 -> 43400 | S15: =IF(H15="New Business",IFERROR((K15/M15)*R15,0),IF(H15="Upsell",K15*'Commission Plan Rules'!$F$9,IF(H15="Renewal",K15*'Commission Plan Rules'!$F$10,0))) -> 90
A16: D00222 | B16: R012 | C16: =IFERROR(INDEX('Sales Roster & Quotas'!$C$6:$C$20,MATCH($B16,'Sales Roster & Quotas'!$B$6:$B$20,0)),"") -> Omar Fischer | D16: =IFERROR(INDEX('Sales Roster & Quotas'!$D$6:$D$20,MATCH($B16,'Sales Roster & Quotas'!$B$6:$B$20,0)),"") -> Mid-Market | E16: 46029 | F16: =TEXT(E16,"yyyy-mm") -> 2026-01 | G16: =IF(MONTH(E16)<=3,"Q1","Q2") -> Q1 | H16: Renewal | I16: Stonebridge Insurance Brokers | J16: Policy Admin Core | K16: 17500 | L16: =IFERROR(INDEX('Sales Roster & Quotas'!$G$6:$G$20,MATCH($B16,'Sales Roster & Quotas'!$B$6:$B$20,0)),0) -> 324000 | M16: =SUMIFS($K$5:$K$274,$B$5:$B$274,$B16,$G$5:$G$274,$G16,$H$5:$H$274,"New Business") -> 457000 | N16: =IFERROR(M16/L16,0) -> 1.4104938 | O16: =MIN(M16,L16) -> 324000 | P16: =MAX(MIN(M16,L16*1.25)-L16,0) -> 81000 | Q16: =MAX(M16-L16*1.25,0) -> 52000 | R16: =O16*'Commission Plan Rules'!$F$6+P16*'Commission Plan Rules'!$F$7+Q16*'Commission Plan Rules'!$F$8 -> 40260 | S16: =IF(H16="New Business",IFERROR((K16/M16)*R16,0),IF(H16="Upsell",K16*'Commission Plan Rules'!$F$9,IF(H16="Renewal",K16*'Commission Plan Rules'!$F$10,0))) -> 525
... A274: D00115 | B274: R006 | C274: =IFERROR(INDEX('Sales Roster & Quotas'!$C$6:$C$20,MATCH($B274,'Sales Roster & Quotas'!$B$6:$B$20,0)),"") -> Marcus Bennett | D274: =IFERROR(INDEX('Sales Roster & Quotas'!$D$6:$D$20,MATCH($B274,'Sales Roster & Quotas'!$B$6:$B$20,0)),"") -> SMB | E274: 46201 | F274: =TEXT(E274,"yyyy-mm") -> 2026-06 | G274: =IF(MONTH(E274)<=3,"Q1","Q2") -> Q2 | H274: New Business | I274: Brookhaven Risk Advisors | J274: Client Portal | K274: 65500 | L274: =IFERROR(INDEX('Sales Roster & Quotas'!$G$6:$G$20,MATCH($B274,'Sales Roster & Quotas'!$B$6:$B$20,0)),0) -> 159000 | M274: =SUMIFS($K$5:$K$274,$B$5:$B$274,$B274,$G$5:$G$274,$G274,$H$5:$H$274,"New Business") -> 200000 | N274: =IFERROR(M274/L274,0) -> 1.2578616 | O274: =MIN(M274,L274) -> 159000 | P274: =MAX(MIN(M274,L274*1.25)-L274,0) -> 39750 | Q274: =MAX(M274-L274*1.25,0) -> 1250 | R274: =O274*'Commission Plan Rules'!$F$6+P274*'Commission Plan Rules'!$F$7+Q274*'Commission Plan Rules'!$F$8 -> 16845 | S274: =IF(H274="New Business",IFERROR((K274/M274)*R274,0),IF(H274="Upsell",K274*'Commission Plan Rules'!$F$9,IF(H274="Renewal",K274*'Commission Plan Rules'!$F$10,0))) -> 5516.7375
I275: TOTAL | K275: =SUM(K5:K274) -> 14074500 | S275: =SUM(S5:S274) -> 916935

Sheet Rep-Quarter Summary
A1: FY26 Commission Summary by Rep & Quarter
A2: Rolled up from Bookings Detail. Attainment below 85% is flagged for coaching; above 125% is flagged for accelerator review.
A4: Rep ID | B4: Rep Name | C4: Segment | D4: Region | E4: Quarter | F4: New Biz ARR | G4: Upsell ARR | H4: Renewal ARR | I4: Total Bookings ARR | J4: Quota | K4: Attainment % | L4: Total Commission | M4: Deal Count
A5: R001 | B5: =INDEX('Sales Roster & Quotas'!$C$6:$C$20,MATCH($A5,'Sales Roster & Quotas'!$B$6:$B$20,0)) -> Maria Chen | C5: =INDEX('Sales Roster & Quotas'!$D$6:$D$20,MATCH($A5,'Sales Roster & Quotas'!$B$6:$B$20,0)) -> SMB | D5: =INDEX('Sales Roster & Quotas'!$E$6:$E$20,MATCH($A5,'Sales Roster & Quotas'!$B$6:$B$20,0)) -> West | E5: Q1 | F5: =SUMIFS('Bookings Detail'!$K$5:$K$274,'Bookings Detail'!$B$5:$B$274,$A5,'Bookings Detail'!$G$5:$G$274,$E5,'Bookings Detail'!$H$5:$H$274,"New Business") -> 142000 | G5: =SUMIFS('Bookings Detail'!$K$5:$K$274,'Bookings Detail'!$B$5:$B$274,$A5,'Bookings Detail'!$G$5:$G$274,$E5,'Bookings Detail'!$H$5:$H$274,"Upsell") -> 53500 | H5: =SUMIFS('Bookings Detail'!$K$5:$K$274,'Bookings Detail'!$B$5:$B$274,$A5,'Bookings Detail'!$G$5:$G$274,$E5,'Bookings Detail'!$H$5:$H$274,"Renewal") -> 74000 | I5: =F5+G5+H5 -> 269500 | J5: =INDEX('Sales Roster & Quotas'!$G$6:$G$20,MATCH($A5,'Sales Roster & Quotas'!$B$6:$B$20,0)) -> 160000 | K5: =IFERROR(F5/J5,0) -> 0.8875 | L5: =SUMIFS('Bookings Detail'!$S$5:$S$274,'Bookings Detail'!$B$5:$B$274,$A5,'Bookings Detail'!$G$5:$G$274,$E5) -> 16790 | M5: =SUMPRODUCT((('Bookings Detail'!$B$5:$B$274=$A5))*(('Bookings Detail'!$G$5:$G$274=$E5))) -> 13
A6: R001 | B6: =INDEX('Sales Roster & Quotas'!$C$6:$C$20,MATCH($A6,'Sales Roster & Quotas'!$B$6:$B$20,0)) -> Maria Chen | C6: =INDEX('Sales Roster & Quotas'!$D$6:$D$20,MATCH($A6,'Sales Roster & Quotas'!$B$6:$B$20,0)) -> SMB | D6: =INDEX('Sales Roster & Quotas'!$E$6:$E$20,MATCH($A6,'Sales Roster & Quotas'!$B$6:$B$20,0)) -> West | E6: Q2 | F6: =SUMIFS('Bookings Detail'!$K$5:$K$274,'Bookings Detail'!$B$5:$B$274,$A6,'Bookings Detail'!$G$5:$G$274,$E6,'Bookings Detail'!$H$5:$H$274,"New Business") -> 113500 | G6: =SUMIFS('Bookings Detail'!$K$5:$K$274,'Bookings Detail'!$B$5:$B$274,$A6,'Bookings Detail'!$G$5:$G$274,$E6,'Bookings Detail'!$H$5:$H$274,"Upsell") -> 84000 | H6: =SUMIFS('Bookings Detail'!$K$5:$K$274,'Bookings Detail'!$B$5:$B$274,$A6,'Bookings Detail'!$G$5:$G$274,$E6,'Bookings Detail'!$H$5:$H$274,"Renewal") -> 79500 | I6: =F6+G6+H6 -> 277000 | J6: =INDEX('Sales Roster & Quotas'!$G$6:$G$20,MATCH($A6,'Sales Roster & Quotas'!$B$6:$B$20,0)) -> 160000 | K6: =IFERROR(F6/J6,0) -> 0.709375 | L6: =SUMIFS('Bookings Detail'!$S$5:$S$274,'Bookings Detail'!$B$5:$B$274,$A6,'Bookings Detail'!$G$5:$G$274,$E6) -> 16505 | M6: =SUMPRODUCT((('Bookings Detail'!$B$5:$B$274=$A6))*(('Bookings Detail'!$G$5:$G$274=$E6))) -> 11
A7: R002 | B7: =INDEX('Sales Roster & Quotas'!$C$6:$C$20,MATCH($A7,'Sales Roster & Quotas'!$B$6:$B$20,0)) -> James Okafor | C7: =INDEX('Sales Roster & Quotas'!$D$6:$D$20,MATCH($A7,'Sales Roster & Quotas'!$B$6:$B$20,0)) -> SMB | D7: =INDEX('Sales Roster & Quotas'!$E$6:$E$20,MATCH($A7,'Sales Roster & Quotas'!$B$6:$B$20,0)) -> West | E7: Q1 | F7: =SUMIFS('Bookings Detail'!$K$5:$K$274,'Bookings Detail'!$B$5:$B$274,$A7,'Bookings Detail'!$G$5:$G$274,$E7,'Bookings Detail'!$H$5:$H$274,"New Business") -> 170500 | G7: =SUMIFS('Bookings Detail'!$K$5:$K$274,'Bookings Detail'!$B$5:$B$274,$A7,'Bookings Detail'!$G$5:$G$274,$E7,'Bookings Detail'!$H$5:$H$274,"Upsell") -> 4500 | H7: =SUMIFS('Bookings Detail'!$K$5:$K$274,'Bookings Detail'!$B$5:$B$274,$A7,'Bookings Detail'!$G$5:$G$274,$E7,'Bookings Detail'!$H$5:$H$274,"Renewal") -> 10000 | I7: =F7+G7+H7 -> 185000 | J7: =INDEX('Sales Roster & Quotas'!$G$6:$G$20,MATCH($A7,'Sales Roster & Quotas'!$B$6:$B$20,0)) -> 135000 | K7: =IFERROR(F7/J7,0) -> 1.262963 | L7: =SUMIFS('Bookings Detail'!$S$5:$S$274,'Bookings Detail'!$B$5:$B$274,$A7,'Bookings Detail'!$G$5:$G$274,$E7) -> 14955 | M7: =SUMPRODUCT((('Bookings Detail'!$B$5:$B$274=$A7))*(('Bookings Detail'!$G$5:$G$274=$E7))) -> 9
A8: R002 | B8: =INDEX('Sales Roster & Quotas'!$C$6:$C$20,MATCH($A8,'Sales Roster & Quotas'!$B$6:$B$20,0)) -> James Okafor | C8: =INDEX('Sales Roster & Quotas'!$D$6:$D$20,MATCH($A8,'Sales Roster & Quotas'!$B$6:$B$20,0)) -> SMB | D8: =INDEX('Sales Roster & Quotas'!$E$6:$E$20,MATCH($A8,'Sales Roster & Quotas'!$B$6:$B$20,0)) -> West | E8: Q2 | F8: =SUMIFS('Bookings Detail'!$K$5:$K$274,'Bookings Detail'!$B$5:$B$274,$A8,'Bookings Detail'!$G$5:$G$274,$E8,'Bookings Detail'!$H$5:$H$274,"New Business") -> 144000 | G8: =SUMIFS('Bookings Detail'!$K$5:$K$274,'Bookings Detail'!$B$5:$B$274,$A8,'Bookings Detail'!$G$5:$G$274,$E8,'Bookings Detail'!$H$5:$H$274,"Upsell") -> 0 | H8: =SUMIFS('Bookings Detail'!$K$5:$K$274,'Bookings Detail'!$B$5:$B$274,$A8,'Bookings Detail'!$G$5:$G$274,$E8,'Bookings Detail'!$H$5:$H$274,"Renewal") -> 13500 | I8: =F8+G8+H8 -> 157500 | J8: =INDEX('Sales Roster & Quotas'!$G$6:$G$20,MATCH($A8,'Sales Roster & Quotas'!$B$6:$B$20,0)) -> 135000 | K8: =IFERROR(F8/J8,0) -> 1.0666667 | L8: =SUMIFS('Bookings Detail'!$S$5:$S$274,'Bookings Detail'!$B$5:$B$274,$A8,'Bookings Detail'!$G$5:$G$274,$E8) -> 12105 | M8: =SUMPRODUCT((('Bookings Detail'!$B$5:$B$274=$A8))*(('Bookings Detail'!$G$5:$G$274=$E8))) -> 8
A9: R003 | B9: =INDEX('Sales Roster & Quotas'!$C$6:$C$20,MATCH($A9,'Sales Roster & Quotas'!$B$6:$B$20,0)) -> Priya Patel | C9: =INDEX('Sales Roster & Quotas'!$D$6:$D$20,MATCH($A9,'Sales Roster & Quotas'!$B$6:$B$20,0)) -> SMB | D9: =INDEX('Sales Roster & Quotas'!$E$6:$E$20,MATCH($A9,'Sales Roster & Quotas'!$B$6:$B$20,0)) -> East | E9: Q1 | F9: =SUMIFS('Bookings Detail'!$K$5:$K$274,'Bookings Detail'!$B$5:$B$274,$A9,'Bookings Detail'!$G$5:$G$274,$E9,'Bookings Detail'!$H$5:$H$274,"New Business") -> 118500 | G9: =SUMIFS('Bookings Detail'!$K$5:$K$274,'Bookings Detail'!$B$5:$B$274,$A9,'Bookings Detail'!$G$5:$G$274,$E9,'Bookings Detail'!$H$5:$H$274,"Upsell") -> 36000 | H9: =SUMIFS('Bookings Detail'!$K$5:$K$274,'Bookings Detail'!$B$5:$B$274,$A9,'Bookings Detail'!$G$5:$G$274,$E9,'Bookings Detail'!$H$5:$H$274,"Renewal") -> 79500 | I9: =F9+G9+H9 -> 234000 | J9: =INDEX('Sales Roster & Quotas'!$G$6:$G$20,MATCH($A9,'Sales Roster & Quotas'!$B$6:$B$20,0)) -> 137000 | K9: =IFERROR(F9/J9,0) -> 0.8649635 | L9: =SUMIFS('Bookings Detail'!$S$5:$S$274,'Bookings Detail'!$B$5:$B$274,$A9,'Bookings Detail'!$G$5:$G$274,$E9) -> 14025 | M9: =SUMPRODUCT((('Bookings Detail'!$B$5:$B$274=$A9))*(('Bookings Detail'!$G$5:$G$274=$E9))) -> 11
A10: R003 | B10: =INDEX('Sales Roster & Quotas'!$C$6:$C$20,MATCH($A10,'Sales Roster & Quotas'!$B$6:$B$20,0)) -> Priya Patel | C10: =INDEX('Sales Roster & Quotas'!$D$6:$D$20,MATCH($A10,'Sales Roster & Quotas'!$B$6:$B$20,0)) -> SMB | D10: =INDEX('Sales Roster & Quotas'!$E$6:$E$20,MATCH($A10,'Sales Roster & Quotas'!$B$6:$B$20,0)) -> East | E10: Q2 | F10: =SUMIFS('Bookings Detail'!$K$5:$K$274,'Bookings Detail'!$B$5:$B$274,$A10,'Bookings Detail'!$G$5:$G$274,$E10,'Bookings Detail'!$H$5:$H$274,"New Business") -> 119000 | G10: =SUMIFS('Bookings Detail'!$K$5:$K$274,'Bookings Detail'!$B$5:$B$274,$A10,'Bookings Detail'!$G$5:$G$274,$E10,'Bookings Detail'!$H$5:$H$274,"Upsell") -> 54500 | H10: =SUMIFS('Bookings Detail'!$K$5:$K$274,'Bookings Detail'!$B$5:$B$274,$A10,'Bookings Detail'!$G$5:$G$274,$E10,'Bookings Detail'!$H$5:$H$274,"Renewal") -> 92500 | I10: =F10+G10+H10 -> 266000 | J10: =INDEX('Sales Roster & Quotas'!$G$6:$G$20,MATCH($A10,'Sales Roster & Quotas'!$B$6:$B$20,0)) -> 137000 | K10: =IFERROR(F10/J10,0) -> 0.86861314 | L10: =SUMIFS('Bookings Detail'!$S$5:$S$274,'Bookings Detail'!$B$5:$B$274,$A10,'Bookings Detail'!$G$5:$G$274,$E10) -> 15565 | M10: =SUMPRODUCT((('Bookings Detail'!$B$5:$B$274=$A10))*(('Bookings Detail'!$G$5:$G$274=$E10))) -> 11
A11: R004 | B11: =INDEX('Sales Roster & Quotas'!$C$6:$C$20,MATCH($A11,'Sales Roster & Quotas'!$B$6:$B$20,0)) -> David Nguyen | C11: =INDEX('Sales Roster & Quotas'!$D$6:$D$20,MATCH($A11,'Sales Roster & Quotas'!$B$6:$B$20,0)) -> SMB | D11: =INDEX('Sales Roster & Quotas'!$E$6:$E$20,MATCH($A11,'Sales Roster & Quotas'!$B$6:$B$20,0)) -> East | E11: Q1 | F11: =SUMIFS('Bookings Detail'!$K$5:$K$274,'Bookings Detail'!$B$5:$B$274,$A11,'Bookings Detail'!$G$5:$G$274,$E11,'Bookings Detail'!$H$5:$H$274,"New Business") -> 196500 | G11: =SUMIFS('Bookings Detail'!$K$5:$K$274,'Bookings Detail'!$B$5:$B$274,$A11,'Bookings Detail'!$G$5:$G$274,$E11,'Bookings Detail'!$H$5:$H$274,"Upsell") -> 37000 | H11: =SUMIFS('Bookings Detail'!$K$5:$K$274,'Bookings Detail'!$B$5:$B$274,$A11,'Bookings Detail'!$G$5:$G$274,$E11,'Bookings Detail'!$H$5:$H$274,"Renewal") -> 38500 | I11: =F11+G11+H11 -> 272000 | J11: =INDEX('Sales Roster & Quotas'!$G$6:$G$20,MATCH($A11,'Sales Roster & Quotas'!$B$6:$B$20,0)) -> 155000 | K11: =IFERROR(F11/J11,0) -> 1.2677419 | L11: =SUMIFS('Bookings Detail'!$S$5:$S$274,'Bookings Detail'!$B$5:$B$274,$A11,'Bookings Detail'!$G$5:$G$274,$E11) -> 19980 | M11: =SUMPRODUCT((('Bookings Detail'!$B$5:$B$274=$A11))*(('Bookings Detail'!$G$5:$G$274=$E11))) -> 11
A12: R004 | B12: =INDEX('Sales Roster & Quotas'!$C$6:$C$20,MATCH($A12,'Sales Roster & Quotas'!$B$6:$B$20,0)) -> David Nguyen | C12: =INDEX('Sales Roster & Quotas'!$D$6:$D$20,MATCH($A12,'Sales Roster & Quotas'!$B$6:$B$20,0)) -> SMB | D12: =INDEX('Sales Roster & Quotas'!$E$6:$E$20,MATCH($A12,'Sales Roster & Quotas'!$B$6:$B$20,0)) -> East | E12: Q2 | F12: =SUMIFS('Bookings Detail'!$K$5:$K$274,'Bookings Detail'!$B$5:$B$274,$A12,'Bookings Detail'!$G$5:$G$274,$E12,'Bookings Detail'!$H$5:$H$274,"New Business") -> 26000 | G12: =SUMIFS('Bookings Detail'!$K$5:$K$274,'Bookings Detail'!$B$5:$B$274,$A12,'Bookings Detail'!$G$5:$G$274,$E12,'Bookings Detail'!$H$5:$H$274,"Upsell") -> 6500 | H12: =SUMIFS('Bookings Detail'!$K$5:$K$274,'Bookings Detail'!$B$5:$B$274,$A12,'Bookings Detail'!$G$5:$G$274,$E12,'Bookings Detail'!$H$5:$H$274,"Renewal") -> 171500 | I12: =F12+G12+H12 -> 204000 | J12: =INDEX('Sales Roster & Quotas'!$G$6:$G$20,MATCH($A12,'Sales Roster & Quotas'!$B$6:$B$20,0)) -> 155000 | K12: =IFERROR(F12/J12,0) -> 0.16774194 | L12: =SUMIFS('Bookings Detail'!$S$5:$S$274,'Bookings Detail'!$B$5:$B$274,$A12,'Bookings Detail'!$G$5:$G$274,$E12) -> 7615 | M12: =SUMPRODUCT((('Bookings Detail'!$B$5:$B$274=$A12))*(('Bookings Detail'!$G$5:$G$274=$E12))) -> 8
A13: R005 | B13: =INDEX('Sales Roster & Quotas'!$C$6:$C$20,MATCH($A13,'Sales Roster & Quotas'!$B$6:$B$20,0)) -> Sofia Rossi | C13: =INDEX('Sales Roster & Quotas'!$D$6:$D$20,MATCH($A13,'Sales Roster & Quotas'!$B$6:$B$20,0)) -> SMB | D13: =INDEX('Sales Roster & Quotas'!$E$6:$E$20,MATCH($A13,'Sales Roster & Quotas'!$B$6:$B$20,0)) -> West | E13: Q1 | F13: =SUMIFS('Bookings Detail'!$K$5:$K$274,'Bookings Detail'!$B$5:$B$274,$A13,'Bookings Detail'!$G$5:$G$274,$E13,'Bookings Detail'!$H$5:$H$274,"New Business") -> 153500 | G13: =SUMIFS('Bookings Detail'!$K$5:$K$274,'Bookings Detail'!$B$5:$B$274,$A13,'Bookings Detail'!$G$5:$G$274,$E13,'Bookings Detail'!$H$5:$H$274,"Upsell") -> 37500 | H13: =SUMIFS('Bookings Detail'!$K$5:$K$274,'Bookings Detail'!$B$5:$B$274,$A13,'Bookings Detail'!$G$5:$G$274,$E13,'Bookings Detail'!$H$5:$H$274,"Renewal") -> 86000 | I13: =F13+G13+H13 -> 277000 | J13: =INDEX('Sales Roster & Quotas'!$G$6:$G$20,MATCH($A13,'Sales Roster & Quotas'!$B$6:$B$20,0)) -> 152000 | K13: =IFERROR(F13/J13,0) -> 1.0098684 | L13: =SUMIFS('Bookings Detail'!$S$5:$S$274,'Bookings Detail'!$B$5:$B$274,$A13,'Bookings Detail'!$G$5:$G$274,$E13) -> 17140 | M13: =SUMPRODUCT((('Bookings Detail'!$B$5:$B$274=$A13))*(('Bookings Detail'!$G$5:$G$274=$E13))) -> 9
A14: R005 | B14: =INDEX('Sales Roster & Quotas'!$C$6:$C$20,MATCH($A14,'Sales Roster & Quotas'!$B$6:$B$20,0)) -> Sofia Rossi | C14: =INDEX('Sales Roster & Quotas'!$D$6:$D$20,MATCH($A14,'Sales Roster & Quotas'!$B$6:$B$20,0)) -> SMB | D14: =INDEX('Sales Roster & Quotas'!$E$6:$E$20,MATCH($A14,'Sales Roster & Quotas'!$B$6:$B$20,0)) -> West | E14: Q2 | F14: =SUMIFS('Bookings Detail'!$K$5:$K$274,'Bookings Detail'!$B$5:$B$274,$A14,'Bookings Detail'!$G$5:$G$274,$E14,'Bookings Detail'!$H$5:$H$274,"New Business") -> 156500 | G14: =SUMIFS('Bookings Detail'!$K$5:$K$274,'Bookings Detail'!$B$5:$B$274,$A14,'Bookings Detail'!$G$5:$G$274,$E14,'Bookings Detail'!$H$5:$H$274,"Upsell") -> 0 | H14: =SUMIFS('Bookings Detail'!$K$5:$K$274,'Bookings Detail'!$B$5:$B$274,$A14,'Bookings Detail'!$G$5:$G$274,$E14,'Bookings Detail'!$H$5:$H$274,"Renewal") -> 87500 | I14: =F14+G14+H14 -> 244000 | J14: =INDEX('Sales Roster & Quotas'!$G$6:$G$20,MATCH($A14,'Sales Roster & Quotas'!$B$6:$B$20,0)) -> 152000 | K14: =IFERROR(F14/J14,0) -> 1.0296053 | L14: =SUMIFS('Bookings Detail'!$S$5:$S$274,'Bookings Detail'!$B$5:$B$274,$A14,'Bookings Detail'!$G$5:$G$274,$E14) -> 15235 | M14: =SUMPRODUCT((('Bookings Detail'!$B$5:$B$274=$A14))*(('Bookings Detail'!$G$5:$G$274=$E14))) -> 10
A15: R006 | B15: =INDEX('Sales Roster & Quotas'!$C$6:$C$20,MATCH($A15,'Sales Roster & Quotas'!$B$6:$B$20,0)) -> Marcus Bennett | C15: =INDEX('Sales Roster & Quotas'!$D$6:$D$20,MATCH($A15,'Sales Roster & Quotas'!$B$6:$B$20,0)) -> SMB | D15: =INDEX('Sales Roster & Quotas'!$E$6:$E$20,MATCH($A15,'Sales Roster & Quotas'!$B$6:$B$20,0)) -> West | E15: Q1 | F15: =SUMIFS('Bookings Detail'!$K$5:$K$274,'Bookings Detail'!$B$5:$B$274,$A15,'Bookings Detail'!$G$5:$G$274,$E15,'Bookings Detail'!$H$5:$H$274,"New Business") -> 174500 | G15: =SUMIFS('Bookings Detail'!$K$5:$K$274,'Bookings Detail'!$B$5:$B$274,$A15,'Bookings Detail'!$G$5:$G$274,$E15,'Bookings Detail'!$H$5:$H$274,"Upsell") -> 64500 | H15: =SUMIFS('Bookings Detail'!$K$5:$K$274,'Bookings Detail'!$B$5:$B$274,$A15,'Bookings Detail'!$G$5:$G$274,$E15,'Bookings Detail'!$H$5:$H$274,"Renewal") -> 97500 | I15: =F15+G15+H15 -> 336500 | J15: =INDEX('Sales Roster & Quotas'!$G$6:$G$20,MATCH($A15,'Sales Roster & Quotas'!$B$6:$B$20,0)) -> 159000 | K15: =IFERROR(F15/J15,0) -> 1.0974843 | L15: =SUMIFS('Bookings Detail'!$S$5:$S$274,'Bookings Detail'!$B$5:$B$274,$A15,'Bookings Detail'!$G$5:$G$274,$E15) -> 21065 | M15: =SUMPRODUCT((('Bookings Detail'!$B$5:$B$274=$A15))*(('Bookings Detail'!$G$5:$G$274=$E15))) -> 12
A16: R006 | B16: =INDEX('Sales Roster & Quotas'!$C$6:$C$20,MATCH($A16,'Sales Roster & Quotas'!$B$6:$B$20,0)) -> Marcus Bennett | C16: =INDEX('Sales Roster & Quotas'!$D$6:$D$20,MATCH($A16,'Sales Roster & Quotas'!$B$6:$B$20,0)) -> SMB | D16: =INDEX('Sales Roster & Quotas'!$E$6:$E$20,MATCH($A16,'Sales Roster & Quotas'!$B$6:$B$20,0)) -> West | E16: Q2 | F16: =SUMIFS('Bookings Detail'!$K$5:$K$274,'Bookings Detail'!$B$5:$B$274,$A16,'Bookings Detail'!$G$5:$G$274,$E16,'Bookings Detail'!$H$5:$H$274,"New Business") -> 200000 | G16: =SUMIFS('Bookings Detail'!$K$5:$K$274,'Bookings Detail'!$B$5:$B$274,$A16,'Bookings Detail'!$G$5:$G$274,$E16,'Bookings Detail'!$H$5:$H$274,"Upsell") -> 93500 | H16: =SUMIFS('Bookings Detail'!$K$5:$K$274,'Bookings Detail'!$B$5:$B$274,$A16,'Bookings Detail'!$G$5:$G$274,$E16,'Bookings Detail'!$H$5:$H$274,"Renewal") -> 85000 | I16: =F16+G16+H16 -> 378500 | J16: =INDEX('Sales Roster & Quotas'!$G$6:$G$20,MATCH($A16,'Sales Roster & Quotas'!$B$6:$B$20,0)) -> 159000 | K16: =IFERROR(F16/J16,0) -> 1.2578616 | L16: =SUMIFS('Bookings Detail'!$S$5:$S$274,'Bookings Detail'!$B$5:$B$274,$A16,'Bookings Detail'!$G$5:$G$274,$E16) -> 25005 | M16: =SUMPRODUCT((('Bookings Detail'!$B$5:$B$274=$A16))*(('Bookings Detail'!$G$5:$G$274=$E16))) -> 13
... A34: R015 | B34: =INDEX('Sales Roster & Quotas'!$C$6:$C$20,MATCH($A34,'Sales Roster & Quotas'!$B$6:$B$20,0)) -> Lucia Larsen | C34: =INDEX('Sales Roster & Quotas'!$D$6:$D$20,MATCH($A34,'Sales Roster & Quotas'!$B$6:$B$20,0)) -> Enterprise | D34: =INDEX('Sales Roster & Quotas'!$E$6:$E$20,MATCH($A34,'Sales Roster & Quotas'!$B$6:$B$20,0)) -> Central | E34: Q2 | F34: =SUMIFS('Bookings Detail'!$K$5:$K$274,'Bookings Detail'!$B$5:$B$274,$A34,'Bookings Detail'!$G$5:$G$274,$E34,'Bookings Detail'!$H$5:$H$274,"New Business") -> 596500 | G34: =SUMIFS('Bookings Detail'!$K$5:$K$274,'Bookings Detail'!$B$5:$B$274,$A34,'Bookings Detail'!$G$5:$G$274,$E34,'Bookings Detail'!$H$5:$H$274,"Upsell") -> 0 | H34: =SUMIFS('Bookings Detail'!$K$5:$K$274,'Bookings Detail'!$B$5:$B$274,$A34,'Bookings Detail'!$G$5:$G$274,$E34,'Bookings Detail'!$H$5:$H$274,"Renewal") -> 248000 | I34: =F34+G34+H34 -> 844500 | J34: =INDEX('Sales Roster & Quotas'!$G$6:$G$20,MATCH($A34,'Sales Roster & Quotas'!$B$6:$B$20,0)) -> 594000 | K34: =IFERROR(F34/J34,0) -> 1.0042088 | L34: =SUMIFS('Bookings Detail'!$S$5:$S$274,'Bookings Detail'!$B$5:$B$274,$A34,'Bookings Detail'!$G$5:$G$274,$E34) -> 55210 | M34: =SUMPRODUCT((('Bookings Detail'!$B$5:$B$274=$A34))*(('Bookings Detail'!$G$5:$G$274=$E34))) -> 6
B35: Company Total | F35: =SUM(F5:F34) -> 8480000 | G35: =SUM(G5:G34) -> 1798500 | H35: =SUM(H5:H34) -> 3796000 | I35: =SUM(I5:I34) -> 14074500 | J35: =SUM(J5:J34) -> 9066000 | K35: =AVERAGE(K5:K34) -> 0.96738655 | L35: =SUM(L5:L34) -> 916935

Sheet Monthly Accrual & Forecast
A1: Monthly Commission Accrual & Q3 FY26 Forecast
A2: Actuals for Jan–Jun are pulled from Bookings Detail. Jul–Sep is a trend-based forecast for budgeting and cash accrual planning — not a commitment.
A4: Month | B4: Bookings ARR | C4: Commission Expense | D4: Commission as % of ARR | E4: Deal Count | F4: Type
A5: 2026-01 | B5: =SUMIFS('Bookings Detail'!$K$5:$K$274,'Bookings Detail'!$F$5:$F$274,$A5) -> 1341500 | C5: =SUMIFS('Bookings Detail'!$S$5:$S$274,'Bookings Detail'!$F$5:$F$274,$A5) -> 85003.042 | D5: =IFERROR(C5/B5,0) -> 0.063364176 | E5: =COUNTIFS('Bookings Detail'!$F$5:$F$274,$A5) -> 44 | F5: Actual
A6: 2026-02 | B6: =SUMIFS('Bookings Detail'!$K$5:$K$274,'Bookings Detail'!$F$5:$F$274,$A6) -> 3145500 | C6: =SUMIFS('Bookings Detail'!$S$5:$S$274,'Bookings Detail'!$F$5:$F$274,$A6) -> 207904.91 | D6: =IFERROR(C6/B6,0) -> 0.066095981 | E6: =COUNTIFS('Bookings Detail'!$F$5:$F$274,$A6) -> 50 | F6: Actual
A7: 2026-03 | B7: =SUMIFS('Bookings Detail'!$K$5:$K$274,'Bookings Detail'!$F$5:$F$274,$A7) -> 2735500 | C7: =SUMIFS('Bookings Detail'!$S$5:$S$274,'Bookings Detail'!$F$5:$F$274,$A7) -> 172902.05 | D7: =IFERROR(C7/B7,0) -> 0.063206745 | E7: =COUNTIFS('Bookings Detail'!$F$5:$F$274,$A7) -> 51 | F7: Actual
A8: 2026-04 | B8: =SUMIFS('Bookings Detail'!$K$5:$K$274,'Bookings Detail'!$F$5:$F$274,$A8) -> 2099000 | C8: =SUMIFS('Bookings Detail'!$S$5:$S$274,'Bookings Detail'!$F$5:$F$274,$A8) -> 131582.1 | D8: =IFERROR(C8/B8,0) -> 0.062687994 | E8: =COUNTIFS('Bookings Detail'!$F$5:$F$274,$A8) -> 45 | F8: Actual
A9: 2026-05 | B9: =SUMIFS('Bookings Detail'!$K$5:$K$274,'Bookings Detail'!$F$5:$F$274,$A9) -> 2559500 | C9: =SUMIFS('Bookings Detail'!$S$5:$S$274,'Bookings Detail'!$F$5:$F$274,$A9) -> 184816.76 | D9: =IFERROR(C9/B9,0) -> 0.072208151 | E9: =COUNTIFS('Bookings Detail'!$F$5:$F$274,$A9) -> 38 | F9: Actual
A10: 2026-06 | B10: =SUMIFS('Bookings Detail'!$K$5:$K$274,'Bookings Detail'!$F$5:$F$274,$A10) -> 2193500 | C10: =SUMIFS('Bookings Detail'!$S$5:$S$274,'Bookings Detail'!$F$5:$F$274,$A10) -> 134726.14 | D10: =IFERROR(C10/B10,0) -> 0.061420623 | E10: =COUNTIFS('Bookings Detail'!$F$5:$F$274,$A10) -> 42 | F10: Actual
A11: 2026-07 | B11: =TREND($B$5:$B$10,ROW($B$5:$B$10)-ROW($B$5)+1,7) -> 2532300 | C11: =B11*AVERAGE($D$5:$D$10) -> 164170.56 | D11: =IFERROR(C11/B11,0) -> 0.064830612 | E11: =ROUND(E10*0.98,0) -> 41 | F11: Forecast
A12: 2026-08 | B12: =TREND($B$5:$B$10,ROW($B$5:$B$10)-ROW($B$5)+1,8) -> 2585600 | C12: =B12*AVERAGE($D$5:$D$10) -> 167626.03 | D12: =IFERROR(C12/B12,0) -> 0.064830612 | E12: =ROUND(E10*0.98,0) -> 41 | F12: Forecast
A13: 2026-09 | B13: =TREND($B$5:$B$10,ROW($B$5:$B$10)-ROW($B$5)+1,9) -> 2638900 | C13: =B13*AVERAGE($D$5:$D$10) -> 171081.5 | D13: =IFERROR(C13/B13,0) -> 0.064830612 | E13: =ROUND(E10*0.98,0) -> 41 | F13: Forecast
A15: Q3 FY26 Forecast Summary
A16: Forecasted Q3 Bookings ARR: | C16: =SUM(B11:B13) -> 7756800
A17: Forecasted Q3 Commission Expense (for budget accrual): | C17: =SUM(C11:C13) -> 502878.09
A18: Method: | C18: Linear trend (TREND function) on 6 months of actuals; commission % applies the trailing 6-month average rate.

Sheet Executive Dashboard
B2: MERIDIAN RISK TECHNOLOGIES
B3: FY26 Sales Commission — Executive Dashboard (H1 Actuals + Q3 Forecast)
T4: Chart source data (linked — do not delete)
B5: Total Bookings ARR (H1) | D5: Total Commission Expense (H1) | F5: Commission as % of Bookings
B6: =SUM('Bookings Detail'!$K$5:$K$274) -> 14074500 | D6: =SUM('Bookings Detail'!$S$5:$S$274) -> 916935 | F6: ='Executive Dashboard'!D6/'Executive Dashboard'!B6 -> 0.065148673 | T6: Month | U6: Bookings ARR | V6: Commission Expense
T7: ='Monthly Accrual & Forecast'!A5 -> 2026-01 | U7: ='Monthly Accrual & Forecast'!B5 -> 1341500 | V7: ='Monthly Accrual & Forecast'!C5 -> 85003.042
T8: ='Monthly Accrual & Forecast'!A6 -> 2026-02 | U8: ='Monthly Accrual & Forecast'!B6 -> 3145500 | V8: ='Monthly Accrual & Forecast'!C6 -> 207904.91
B9: Avg Attainment (all reps, both qtrs) | D9: Reps at/above 100% Attainment | F9: Reps below 85% Attainment | T9: ='Monthly Accrual & Forecast'!A7 -> 2026-03 | U9: ='Monthly Accrual & Forecast'!B7 -> 2735500 | V9: ='Monthly Accrual & Forecast'!C7 -> 172902.05
B10: =AVERAGE('Rep-Quarter Summary'!$K$5:$K$34) -> 0.96738655 | D10: =COUNTIF('Rep-Quarter Summary'!$K$5:$K$34,">=1") -> 12 | F10: =COUNTIF('Rep-Quarter Summary'!$K$5:$K$34,"<0.85") -> 7 | T10: ='Monthly Accrual & Forecast'!A8 -> 2026-04 | U10: ='Monthly Accrual & Forecast'!B8 -> 2099000 | V10: ='Monthly Accrual & Forecast'!C8 -> 131582.1
T11: ='Monthly Accrual & Forecast'!A9 -> 2026-05 | U11: ='Monthly Accrual & Forecast'!B9 -> 2559500 | V11: ='Monthly Accrual & Forecast'!C9 -> 184816.76
T12: ='Monthly Accrual & Forecast'!A10 -> 2026-06 | U12: ='Monthly Accrual & Forecast'!B10 -> 2193500 | V12: ='Monthly Accrual & Forecast'!C10 -> 134726.14
T13: ='Monthly Accrual & Forecast'!A11 -> 2026-07 | U13: ='Monthly Accrual & Forecast'!B11 -> 2532300 | V13: ='Monthly Accrual & Forecast'!C11 -> 164170.56
T14: ='Monthly Accrual & Forecast'!A12 -> 2026-08 | U14: ='Monthly Accrual & Forecast'!B12 -> 2585600 | V14: ='Monthly Accrual & Forecast'!C12 -> 167626.03
T15: ='Monthly Accrual & Forecast'!A13 -> 2026-09 | U15: ='Monthly Accrual & Forecast'!B13 -> 2638900 | V15: ='Monthly Accrual & Forecast'!C13 -> 171081.5
T18: Rep | U18: Q2 Attainment
T19: ='Rep-Quarter Summary'!B6 -> Maria Chen | U19: ='Rep-Quarter Summary'!K6 -> 0.709375
T20: ='Rep-Quarter Summary'!B8 -> James Okafor | U20: ='Rep-Quarter Summary'!K8 -> 1.0666667
T21: ='Rep-Quarter Summary'!B10 -> Priya Patel | U21: ='Rep-Quarter Summary'!K10 -> 0.86861314
T22: ='Rep-Quarter Summary'!B12 -> David Nguyen | U22: ='Rep-Quarter Summary'!K12 -> 0.16774194
T23: ='Rep-Quarter Summary'!B14 -> Sofia Rossi | U23: ='Rep-Quarter Summary'!K14 -> 1.0296053
T24: ='Rep-Quarter Summary'!B16 -> Marcus Bennett | U24: ='Rep-Quarter Summary'!K16 -> 1.2578616
T25: ='Rep-Quarter Summary'!B18 -> Elena Kowalski | U25: ='Rep-Quarter Summary'!K18 -> 0.7828125
T26: ='Rep-Quarter Summary'!B20 -> Tyler Alvarez | U26: ='Rep-Quarter Summary'!K20 -> 1.1436364
T27: ='Rep-Quarter Summary'!B22 -> Aisha Kim | U27: ='Rep-Quarter Summary'!K22 -> 0.8815331
T28: ='Rep-Quarter Summary'!B24 -> Ryan Sullivan | U28: ='Rep-Quarter Summary'!K24 -> 1.1245421
T29: ='Rep-Quarter Summary'!B26 -> Natalie Reyes | U29: ='Rep-Quarter Summary'!K26 -> 0.99491525
T30: ='Rep-Quarter Summary'!B28 -> Omar Fischer | U30: ='Rep-Quarter Summary'!K28 -> 1.7762346
T31: ='Rep-Quarter Summary'!B30 -> Grace Adeyemi | U31: ='Rep-Quarter Summary'!K30 -> 0.59744409
T32: ='Rep-Quarter Summary'!B32 -> Kevin Novak | U32: ='Rep-Quarter Summary'!K32 -> 0.88923557
T33: ='Rep-Quarter Summary'!B34 -> Lucia Larsen | U33: ='Rep-Quarter Summary'!K34 -> 1.0042088
T35: Deal Type | U35: ARR
T36: New Business | U36: =SUMIF('Bookings Detail'!$H$5:$H$274,T36,'Bookings Detail'!$K$5:$K$274) -> 8480000
T37: Upsell | U37: =SUMIF('Bookings Detail'!$H$5:$H$274,T37,'Bookings Detail'!$K$5:$K$274) -> 1798500
T38: Renewal | U38: =SUMIF('Bookings Detail'!$H$5:$H$274,T38,'Bookings Detail'!$K$5:$K$274) -> 3796000
T41: Segment | U41: Renewed ARR | V41: Eligible Book | W41: NRR
T42: SMB | U42: =SUMPRODUCT(('Bookings Detail'!$H$5:$H$274="Renewal")*('Bookings Detail'!$D$5:$D$274=T42)*'Bookings Detail'!$K$5:$K$274) -> 915000 | V42: =SUMIF('Sales Roster & Quotas'!$D$6:$D$20,T42,'Sales Roster & Quotas'!$H$6:$H$20)*0.5 -> 734500 | W42: =IFERROR(U42/V42,0) -> 1.2457454
T43: Mid-Market | U43: =SUMPRODUCT(('Bookings Detail'!$H$5:$H$274="Renewal")*('Bookings Detail'!$D$5:$D$274=T43)*'Bookings Detail'!$K$5:$K$274) -> 1371500 | V43: =SUMIF('Sales Roster & Quotas'!$D$6:$D$20,T43,'Sales Roster & Quotas'!$H$6:$H$20)*0.5 -> 1382000 | W43: =IFERROR(U43/V43,0) -> 0.99240232
T44: Enterprise | U44: =SUMPRODUCT(('Bookings Detail'!$H$5:$H$274="Renewal")*('Bookings Detail'!$D$5:$D$274=T44)*'Bookings Detail'!$K$5:$K$274) -> 1509500 | V44: =SUMIF('Sales Roster & Quotas'!$D$6:$D$20,T44,'Sales Roster & Quotas'!$H$6:$H$20)*0.5 -> 1563000 | W44: =IFERROR(U44/V44,0) -> 0.96577095
B62: Key Takeaways
B63: • | C63: Mid-Market rep Omar Fischer is running at 178% of quota in Q2 — flag for accelerator payout review and a look at whether his territory quota was set too low.
...

Sheet Scenario Planner
B2: Commission Plan Scenario Planner
B3: What-if analysis: change the plan rates or quota below and see the resulting company-wide commission expense, holding actual H1 bookings behavior constant. Used to model plan changes before proposing them.
B5: Scenario Inputs
B6: New Biz Tier 1 rate (0-100% attainment) | D6: 0.08
B7: New Biz Tier 2 rate (100-125% attainment) | D7: 0.1
B8: New Biz Tier 3 rate (125%+ attainment) | D8: 0.12
B9: Upsell flat rate | D9: 0.06
B10: Renewal flat rate | D10: 0.03
B11: Quota adjustment (+/-, applied to all reps) | D11: 0
B12: Base plan rates shown in Commission Plan Rules tab for comparison.
B15: Scenario Recalculation — Rep x Quarter (bookings held constant, rates/quota changed)
B17: Rep ID | C17: Rep Name | D17: Quarter | E17: New Biz ARR | F17: Upsell ARR | G17: Renewal ARR | H17: Scenario Quota | I17: Scenario Attainment % | J17: Scenario Tier 1 | K17: Scenario Tier 2 | L17: Scenario Tier 3 | M17: Scenario New Biz Comm. | N17: Scenario Upsell Comm. | O17: Scenario Renewal Comm. | P17: Scenario Total Commission
B18: ='Rep-Quarter Summary'!A5 -> R001 | C18: ='Rep-Quarter Summary'!B5 -> Maria Chen | D18: ='Rep-Quarter Summary'!E5 -> Q1 | E18: ='Rep-Quarter Summary'!F5 -> 142000 | F18: ='Rep-Quarter Summary'!G5 -> 53500 | G18: ='Rep-Quarter Summary'!H5 -> 74000 | H18: ='Rep-Quarter Summary'!J5*(1+$D$11) -> 160000 | I18: =IFERROR(E18/H18,0) -> 0.8875 | J18: =MIN(E18,H18) -> 142000 | K18: =MAX(MIN(E18,H18*1.25)-H18,0) -> 0 | L18: =MAX(E18-H18*1.25,0) -> 0 | M18: =J18*$D$6+K18*$D$7+L18*$D$8 -> 11360 | N18: =F18*$D$9 -> 3210 | O18: =G18*$D$10 -> 2220 | P18: =M18+N18+O18 -> 16790
B19: ='Rep-Quarter Summary'!A6 -> R001 | C19: ='Rep-Quarter Summary'!B6 -> Maria Chen | D19: ='Rep-Quarter Summary'!E6 -> Q2 | E19: ='Rep-Quarter Summary'!F6 -> 113500 | F19: ='Rep-Quarter Summary'!G6 -> 84000 | G19: ='Rep-Quarter Summary'!H6 -> 79500 | H19: ='Rep-Quarter Summary'!J6*(1+$D$11) -> 160000 | I19: =IFERROR(E19/H19,0) -> 0.709375 | J19: =MIN(E19,H19) -> 113500 | K19: =MAX(MIN(E19,H19*1.25)-H19,0) -> 0 | L19: =MAX(E19-H19*1.25,0) -> 0 | M19: =J19*$D$6+K19*$D$7+L19*$D$8 -> 9080 | N19: =F19*$D$9 -> 5040 | O19: =G19*$D$10 -> 2385 | P19: =M19+N19+O19 -> 16505
B20: ='Rep-Quarter Summary'!A7 -> R002 | C20: ='Rep-Quarter Summary'!B7 -> James Okafor | D20: ='Rep-Quarter Summary'!E7 -> Q1 | E20: ='Rep-Quarter Summary'!F7 -> 170500 | F20: ='Rep-Quarter Summary'!G7 -> 4500 | G20: ='Rep-Quarter Summary'!H7 -> 10000 | H20: ='Rep-Quarter Summary'!J7*(1+$D$11) -> 135000 | I20: =IFERROR(E20/H20,0) -> 1.262963 | J20: =MIN(E20,H20) -> 135000 | K20: =MAX(MIN(E20,H20*1.25)-H20,0) -> 33750 | L20: =MAX(E20-H20*1.25,0) -> 1750 | M20: =J20*$D$6+K20*$D$7+L20*$D$8 -> 14385 | N20: =F20*$D$9 -> 270 | O20: =G20*$D$10 -> 300 | P20: =M20+N20+O20 -> 14955
B21: ='Rep-Quarter Summary'!A8 -> R002 | C21: ='Rep-Quarter Summary'!B8 -> James Okafor | D21: ='Rep-Quarter Summary'!E8 -> Q2 | E21: ='Rep-Quarter Summary'!F8 -> 144000 | F21: ='Rep-Quarter Summary'!G8 -> 0 | G21: ='Rep-Quarter Summary'!H8 -> 13500 | H21: ='Rep-Quarter Summary'!J8*(1+$D$11) -> 135000 | I21: =IFERROR(E21/H21,0) -> 1.0666667 | J21: =MIN(E21,H21) -> 135000 | K21: =MAX(MIN(E21,H21*1.25)-H21,0) -> 9000 | L21: =MAX(E21-H21*1.25,0) -> 0 | M21: =J21*$D$6+K21*$D$7+L21*$D$8 -> 11700 | N21: =F21*$D$9 -> 0 | O21: =G21*$D$10 -> 405 | P21: =M21+N21+O21 -> 12105
B22: ='Rep-Quarter Summary'!A9 -> R003 | C22: ='Rep-Quarter Summary'!B9 -> Priya Patel | D22: ='Rep-Quarter Summary'!E9 -> Q1 | E22: ='Rep-Quarter Summary'!F9 -> 118500 | F22: ='Rep-Quarter Summary'!G9 -> 36000 | G22: ='Rep-Quarter Summary'!H9 -> 79500 | H22: ='Rep-Quarter Summary'!J9*(1+$D$11) -> 137000 | I22: =IFERROR(E22/H22,0) -> 0.8649635 | J22: =MIN(E22,H22) -> 118500 | K22: =MAX(MIN(E22,H22*1.25)-H22,0) -> 0 | L22: =MAX(E22-H22*1.25,0) -> 0 | M22: =J22*$D$6+K22*$D$7+L22*$D$8 -> 9480 | N22: =F22*$D$9 -> 2160 | O22: =G22*$D$10 -> 2385 | P22: =M22+N22+O22 -> 14025
B23: ='Rep-Quarter Summary'!A10 -> R003 | C23: ='Rep-Quarter Summary'!B10 -> Priya Patel | D23: ='Rep-Quarter Summary'!E10 -> Q2 | E23: ='Rep-Quarter Summary'!F10 -> 119000 | F23: ='Rep-Quarter Summary'!G10 -> 54500 | G23: ='Rep-Quarter Summary'!H10 -> 92500 | H23: ='Rep-Quarter Summary'!J10*(1+$D$11) -> 137000 | I23: =IFERROR(E23/H23,0) -> 0.86861314 | J23: =MIN(E23,H23) -> 119000 | K23: =MAX(MIN(E23,H23*1.25)-H23,0) -> 0 | L23: =MAX(E23-H23*1.25,0) -> 0 | M23: =J23*$D$6+K23*$D$7+L23*$D$8 -> 9520 | N23: =F23*$D$9 -> 3270 | O23: =G23*$D$10 -> 2775 | P23: =M23+N23+O23 -> 15565
B24: ='Rep-Quarter Summary'!A11 -> R004 | C24: ='Rep-Quarter Summary'!B11 -> David Nguyen | D24: ='Rep-Quarter Summary'!E11 -> Q1 | E24: ='Rep-Quarter Summary'!F11 -> 196500 | F24: ='Rep-Quarter Summary'!G11 -> 37000 | G24: ='Rep-Quarter Summary'!H11 -> 38500 | H24: ='Rep-Quarter Summary'!J11*(1+$D$11) -> 155000 | I24: =IFERROR(E24/H24,0) -> 1.2677419 | J24: =MIN(E24,H24) -> 155000 | K24: =MAX(MIN(E24,H24*1.25)-H24,0) -> 38750 | L24: =MAX(E24-H24*1.25,0) -> 2750 | M24: =J24*$D$6+K24*$D$7+L24*$D$8 -> 16605 | N24: =F24*$D$9 -> 2220 | O24: =G24*$D$10 -> 1155 | P24: =M24+N24+O24 -> 19980
B25: ='Rep-Quarter Summary'!A12 -> R004 | C25: ='Rep-Quarter Summary'!B12 -> David Nguyen | D25: ='Rep-Quarter Summary'!E12 -> Q2 | E25: ='Rep-Quarter Summary'!F12 -> 26000 | F25: ='Rep-Quarter Summary'!G12 -> 6500 | G25: ='Rep-Quarter Summary'!H12 -> 171500 | H25: ='Rep-Quarter Summary'!J12*(1+$D$11) -> 155000 | I25: =IFERROR(E25/H25,0) -> 0.16774194 | J25: =MIN(E25,H25) -> 26000 | K25: =MAX(MIN(E25,H25*1.25)-H25,0) -> 0 | L25: =MAX(E25-H25*1.25,0) -> 0 | M25: =J25*$D$6+K25*$D$7+L25*$D$8 -> 2080 | N25: =F25*$D$9 -> 390 | O25: =G25*$D$10 -> 5145 | P25: =M25+N25+O25 -> 7615
B26: ='Rep-Quarter Summary'!A13 -> R005 | C26: ='Rep-Quarter Summary'!B13 -> Sofia Rossi | D26: ='Rep-Quarter Summary'!E13 -> Q1 | E26: ='Rep-Quarter Summary'!F13 -> 153500 | F26: ='Rep-Quarter Summary'!G13 -> 37500 | G26: ='Rep-Quarter Summary'!H13 -> 86000 | H26: ='Rep-Quarter Summary'!J13*(1+$D$11) -> 152000 | I26: =IFERROR(E26/H26,0) -> 1.0098684 | J26: =MIN(E26,H26) -> 152000 | K26: =MAX(MIN(E26,H26*1.25)-H26,0) -> 1500 | L26: =MAX(E26-H26*1.25,0) -> 0 | M26: =J26*$D$6+K26*$D$7+L26*$D$8 -> 12310 | N26: =F26*$D$9 -> 2250 | O26: =G26*$D$10 -> 2580 | P26: =M26+N26+O26 -> 17140
B27: ='Rep-Quarter Summary'!A14 -> R005 | C27: ='Rep-Quarter Summary'!B14 -> Sofia Rossi | D27: ='Rep-Quarter Summary'!E14 -> Q2 | E27: ='Rep-Quarter Summary'!F14 -> 156500 | F27: ='Rep-Quarter Summary'!G14 -> 0 | G27: ='Rep-Quarter Summary'!H14 -> 87500 | H27: ='Rep-Quarter Summary'!J14*(1+$D$11) -> 152000 | I27: =IFERROR(E27/H27,0) -> 1.0296053 | J27: =MIN(E27,H27) -> 152000 | K27: =MAX(MIN(E27,H27*1.25)-H27,0) -> 4500 | L27: =MAX(E27-H27*1.25,0) -> 0 | M27: =J27*$D$6+K27*$D$7+L27*$D$8 -> 12610 | N27: =F27*$D$9 -> 0 | O27: =G27*$D$10 -> 2625 | P27: =M27+N27+O27 -> 15235
B28: ='Rep-Quarter Summary'!A15 -> R006 | C28: ='Rep-Quarter Summary'!B15 -> Marcus Bennett | D28: ='Rep-Quarter Summary'!E15 -> Q1 | E28: ='Rep-Quarter Summary'!F15 -> 174500 | F28: ='Rep-Quarter Summary'!G15 -> 64500 | G28: ='Rep-Quarter Summary'!H15 -> 97500 | H28: ='Rep-Quarter Summary'!J15*(1+$D$11) -> 159000 | I28: =IFERROR(E28/H28,0) -> 1.0974843 | J28: =MIN(E28,H28) -> 159000 | K28: =MAX(MIN(E28,H28*1.25)-H28,0) -> 15500 | L28: =MAX(E28-H28*1.25,0) -> 0 | M28: =J28*$D$6+K28*$D$7+L28*$D$8 -> 14270 | N28: =F28*$D$9 -> 3870 | O28: =G28*$D$10 -> 2925 | P28: =M28+N28+O28 -> 21065
B29: ='Rep-Quarter Summary'!A16 -> R006 | C29: ='Rep-Quarter Summary'!B16 -> Marcus Bennett | D29: ='Rep-Quarter Summary'!E16 -> Q2 | E29: ='Rep-Quarter Summary'!F16 -> 200000 | F29: ='Rep-Quarter Summary'!G16 -> 93500 | G29: ='Rep-Quarter Summary'!H16 -> 85000 | H29: ='Rep-Quarter Summary'!J16*(1+$D$11) -> 159000 | I29: =IFERROR(E29/H29,0) -> 1.2578616 | J29: =MIN(E29,H29) -> 159000 | K29: =MAX(MIN(E29,H29*1.25)-H29,0) -> 39750 | L29: =MAX(E29-H29*1.25,0) -> 1250 | M29: =J29*$D$6+K29*$D$7+L29*$D$8 -> 16845 | N29: =F29*$D$9 -> 5610 | O29: =G29*$D$10 -> 2550 | P29: =M29+N29+O29 -> 25005
... B47: ='Rep-Quarter Summary'!A34 -> R015 | C47: ='Rep-Quarter Summary'!B34 -> Lucia Larsen | D47: ='Rep-Quarter Summary'!E34 -> Q2 | E47: ='Rep-Quarter Summary'!F34 -> 596500 | F47: ='Rep-Quarter Summary'!G34 -> 0 | G47: ='Rep-Quarter Summary'!H34 -> 248000 | H47: ='Rep-Quarter Summary'!J34*(1+$D$11) -> 594000 | I47: =IFERROR(E47/H47,0) -> 1.0042088 | J47: =MIN(E47,H47) -> 594000 | K47: =MAX(MIN(E47,H47*1.25)-H47,0) -> 2500 | L47: =MAX(E47-H47*1.25,0) -> 0 | M47: =J47*$D$6+K47*$D$7+L47*$D$8 -> 47770 | N47: =F47*$D$9 -> 0 | O47: =G47*$D$10 -> 7440 | P47: =M47+N47+O47 -> 55210
B49: Base Plan vs. Scenario — Total Commission Expense
B50: Base plan (actual rates, actual quota): | D50: =SUM('Rep-Quarter Summary'!L5:L34) -> 916935
B51: Scenario plan (rates/quota above): | D51: =SUM(P18:P47) -> 916935
B52: Dollar impact of scenario: | D52: =D51-D50 -> 0
B53: Percent impact: | D53: =IFERROR(D52/D50,0) -> 0

Sheet Audit & Exceptions
B2: Audit & Exceptions
B3: Automated flags a reviewing analyst would check before commission is paid out. Section A flags rep-quarter attainment outliers; Section B flags individual deals far above a rep's typical deal size for that type. Click the filter arrow on the Flag column to isolate flagged rows.
B5: Rep-Quarter flags: | D5: =COUNTIF(I10:I39,"<>")-COUNTIF(I10:I39,"") -> 3 | F5: Deal-level outlier flags: | H5: =COUNTIF(H45:H314,"<>")-COUNTIF(H45:H314,"") -> 9
B7: Section A — Rep-Quarter Attainment Exceptions
B9: Rep ID | C9: Rep Name | D9: Segment | E9: Quarter | F9: Attainment % | G9: Renewal ARR | H9: Deal Count | I9: Flag
B10: ='Rep-Quarter Summary'!A5 -> R001 | C10: ='Rep-Quarter Summary'!B5 -> Maria Chen | D10: ='Rep-Quarter Summary'!C5 -> SMB | E10: ='Rep-Quarter Summary'!E5 -> Q1 | F10: ='Rep-Quarter Summary'!K5 -> 0.8875 | G10: ='Rep-Quarter Summary'!H5 -> 74000 | H10: ='Rep-Quarter Summary'!M5 -> 13 | I10: =IF(F10>1.5,"Accelerator review — attainment over 150%",IF(F10<0.6,"Coaching flag — attainment under 60%",IF(G10=0,"Retention gap — zero renewals this quarter","")))
B11: ='Rep-Quarter Summary'!A6 -> R001 | C11: ='Rep-Quarter Summary'!B6 -> Maria Chen | D11: ='Rep-Quarter Summary'!C6 -> SMB | E11: ='Rep-Quarter Summary'!E6 -> Q2 | F11: ='Rep-Quarter Summary'!K6 -> 0.709375 | G11: ='Rep-Quarter Summary'!H6 -> 79500 | H11: ='Rep-Quarter Summary'!M6 -> 11 | I11: =IF(F11>1.5,"Accelerator review — attainment over 150%",IF(F11<0.6,"Coaching flag — attainment under 60%",IF(G11=0,"Retention gap — zero renewals this quarter","")))
B12: ='Rep-Quarter Summary'!A7 -> R002 | C12: ='Rep-Quarter Summary'!B7 -> James Okafor | D12: ='Rep-Quarter Summary'!C7 -> SMB | E12: ='Rep-Quarter Summary'!E7 -> Q1 | F12: ='Rep-Quarter Summary'!K7 -> 1.262963 | G12: ='Rep-Quarter Summary'!H7 -> 10000 | H12: ='Rep-Quarter Summary'!M7 -> 9 | I12: =IF(F12>1.5,"Accelerator review — attainment over 150%",IF(F12<0.6,"Coaching flag — attainment under 60%",IF(G12=0,"Retention gap — zero renewals this quarter","")))
B13: ='Rep-Quarter Summary'!A8 -> R002 | C13: ='Rep-Quarter Summary'!B8 -> James Okafor | D13: ='Rep-Quarter Summary'!C8 -> SMB | E13: ='Rep-Quarter Summary'!E8 -> Q2 | F13: ='Rep-Quarter Summary'!K8 -> 1.0666667 | G13: ='Rep-Quarter Summary'!H8 -> 13500 | H13: ='Rep-Quarter Summary'!M8 -> 8 | I13: =IF(F13>1.5,"Accelerator review — attainment over 150%",IF(F13<0.6,"Coaching flag — attainment under 60%",IF(G13=0,"Retention gap — zero renewals this quarter","")))
B14: ='Rep-Quarter Summary'!A9 -> R003 | C14: ='Rep-Quarter Summary'!B9 -> Priya Patel | D14: ='Rep-Quarter Summary'!C9 -> SMB | E14: ='Rep-Quarter Summary'!E9 -> Q1 | F14: ='Rep-Quarter Summary'!K9 -> 0.8649635 | G14: ='Rep-Quarter Summary'!H9 -> 79500 | H14: ='Rep-Quarter Summary'!M9 -> 11 | I14: =IF(F14>1.5,"Accelerator review — attainment over 150%",IF(F14<0.6,"Coaching flag — attainment under 60%",IF(G14=0,"Retention gap — zero renewals this quarter","")))
B15: ='Rep-Quarter Summary'!A10 -> R003 | C15: ='Rep-Quarter Summary'!B10 -> Priya Patel | D15: ='Rep-Quarter Summary'!C10 -> SMB | E15: ='Rep-Quarter Summary'!E10 -> Q2 | F15: ='Rep-Quarter Summary'!K10 -> 0.86861314 | G15: ='Rep-Quarter Summary'!H10 -> 92500 | H15: ='Rep-Quarter Summary'!M10 -> 11 | I15: =IF(F15>1.5,"Accelerator review — attainment over 150%",IF(F15<0.6,"Coaching flag — attainment under 60%",IF(G15=0,"Retention gap — zero renewals this quarter","")))
B16: ='Rep-Quarter Summary'!A11 -> R004 | C16: ='Rep-Quarter Summary'!B11 -> David Nguyen | D16: ='Rep-Quarter Summary'!C11 -> SMB | E16: ='Rep-Quarter Summary'!E11 -> Q1 | F16: ='Rep-Quarter Summary'!K11 -> 1.2677419 | G16: ='Rep-Quarter Summary'!H11 -> 38500 | H16: ='Rep-Quarter Summary'!M11 -> 11 | I16: =IF(F16>1.5,"Accelerator review — attainment over 150%",IF(F16<0.6,"Coaching flag — attainment under 60%",IF(G16=0,"Retention gap — zero renewals this quarter","")))
B17: ='Rep-Quarter Summary'!A12 -> R004 | C17: ='Rep-Quarter Summary'!B12 -> David Nguyen | D17: ='Rep-Quarter Summary'!C12 -> SMB | E17: ='Rep-Quarter Summary'!E12 -> Q2 | F17: ='Rep-Quarter Summary'!K12 -> 0.16774194 | G17: ='Rep-Quarter Summary'!H12 -> 171500 | H17: ='Rep-Quarter Summary'!M12 -> 8 | I17: =IF(F17>1.5,"Accelerator review — attainment over 150%",IF(F17<0.6,"Coaching flag — attainment under 60%",IF(G17=0,"Retention gap — zero renewals this quarter",""))) -> Coaching flag — attainment under 60%
B18: ='Rep-Quarter Summary'!A13 -> R005 | C18: ='Rep-Quarter Summary'!B13 -> Sofia Rossi | D18: ='Rep-Quarter Summary'!C13 -> SMB | E18: ='Rep-Quarter Summary'!E13 -> Q1 | F18: ='Rep-Quarter Summary'!K13 -> 1.0098684 | G18: ='Rep-Quarter Summary'!H13 -> 86000 | H18: ='Rep-Quarter Summary'!M13 -> 9 | I18: =IF(F18>1.5,"Accelerator review — attainment over 150%",IF(F18<0.6,"Coaching flag — attainment under 60%",IF(G18=0,"Retention gap — zero renewals this quarter","")))
B19: ='Rep-Quarter Summary'!A14 -> R005 | C19: ='Rep-Quarter Summary'!B14 -> Sofia Rossi | D19: ='Rep-Quarter Summary'!C14 -> SMB | E19: ='Rep-Quarter Summary'!E14 -> Q2 | F19: ='Rep-Quarter Summary'!K14 -> 1.0296053 | G19: ='Rep-Quarter Summary'!H14 -> 87500 | H19: ='Rep-Quarter Summary'!M14 -> 10 | I19: =IF(F19>1.5,"Accelerator review — attainment over 150%",IF(F19<0.6,"Coaching flag — attainment under 60%",IF(G19=0,"Retention gap — zero renewals this quarter","")))
B20: ='Rep-Quarter Summary'!A15 -> R006 | C20: ='Rep-Quarter Summary'!B15 -> Marcus Bennett | D20: ='Rep-Quarter Summary'!C15 -> SMB | E20: ='Rep-Quarter Summary'!E15 -> Q1 | F20: ='Rep-Quarter Summary'!K15 -> 1.0974843 | G20: ='Rep-Quarter Summary'!H15 -> 97500 | H20: ='Rep-Quarter Summary'!M15 -> 12 | I20: =IF(F20>1.5,"Accelerator review — attainment over 150%",IF(F20<0.6,"Coaching flag — attainment under 60%",IF(G20=0,"Retention gap — zero renewals this quarter","")))
